<?xml version="1.0"?>
<robot xmlns:xacro="http://www.ros.org/wiki/xacro" name="Scottbot">

  <!-- Materials -->
  
  <material name="darkgray">
    <color rgba="0.3 0.3 0.3 1"/>
  </material>

  <material name="lightgray">
    <color rgba="0.7 0.7 0.7 1"/>
  </material>

  <material name="red">
    <color rgba="0.7 0.3 0.3 1"/>
  </material>

  <material name="green">
    <color rgba="0.3 0.7 0.3 1"/>
  </material>

  <material name="blue">
    <color rgba="0.3 0.3 0.7 1"/>
  </material>


  <!-- Macros -->
  
  <xacro:macro name="default_inertial" params="mass">
    <inertial>
      <mass value="${mass}" />
      <inertia ixx="1.0" ixy="0.0" ixz="0.0"
	       iyy="1.0" iyz="0.0"
	       izz="1.0" />
    </inertial>
  </xacro:macro>


  <!-- Links -->
  
  <link name="base_link">
    <visual>
      <geometry>
	<box size="0.070 0.110 0.023"/>
      </geometry>
      <material name="darkgray"/>
    </visual>
  </link>
  
  <link name="left_plate">
    <visual>
      <geometry>
	<box size="0.070 0.110 0.002"/>
      </geometry>
      <origin xyz="0.000 0.055 0.000" rpy="0 0 0"/>
      <material name="lightgray"/>
    </visual>
  </link>

  <link name="right_plate">
    <visual>
      <geometry>
	<box size="0.070 0.110 0.002"/>
      </geometry>
      <origin xyz="0.000 -0.055 0.000" rpy="0 0 0"/>
      <material name="lightgray"/>
    </visual>
  </link>

  <link name="rear_link">
    <visual>
      <geometry>
	<box size="0.058 0.096 0.002"/>
      </geometry>
      <origin xyz="-0.029 0 0"/>
      <material name="lightgray"/>
    </visual>
    <visual>
      <geometry>
	<box size="0.052 0.033 0.002"/>
      </geometry>
      <origin xyz="${-0.058 - 0.052/2} ${(0.096/2 - 0.033/2)} 0"/>
    </visual>
    <visual>
      <geometry>
	<box size="0.052 0.033 0.002"/>
      </geometry>
      <origin xyz="${-0.058 - 0.052/2} ${-(0.096/2 - 0.033/2)} 0"/>
    </visual>
  </link>
  
  <link name="top_plate">
    <visual>
      <geometry>
	<box size="0.022 0.110 0.002"/>
      </geometry>
      <origin xyz="0.011 0 0"/>
      <material name="lightgray"/>
    </visual>
    <visual>
      <geometry>
	<box size="0.068 0.030 0.002"/>
      </geometry>
      <origin xyz="${0.022 + 0.068/2} ${(0.110/2 - 0.030/2)} 0"/>
    </visual>
    <visual>
      <geometry>
	<box size="0.068 0.030 0.002"/>
      </geometry>
      <origin xyz="${0.022 + 0.068/2} ${-(0.110/2 - 0.030/2)} 0"/>
    </visual>
  </link>

  <link name="omni_wheel">
    <visual>
      <geometry>
	<cylinder length="0.020" radius="0.0315"/>
      </geometry>
      <material name="blue"/>
      <origin xyz="0 0 0" rpy="0 0 0"/>
    </visual>
  </link>

  <link name="wheel_L">
    <visual>
      <geometry>
	<cylinder length="0.0065" radius="0.0235"/>
      </geometry>
      <material name="blue"/>
      <origin xyz="0 0 -0.00325" rpy="0 0 0"/>
    </visual>
  </link>
  

  <link name="wheel_R">
    <visual>
      <geometry>
	<cylinder length="0.0065" radius="0.0235"/>
      </geometry>
      <material name="blue"/>
      <origin xyz="0 0 0.00325" rpy="0 0 0"/>
    </visual>
  </link>

  <link name="neck_yaw">
    <visual>
      <geometry>
	<box size="0.020 0.040 0.050"/>
      </geometry>
      <material name="darkgray"/>
      <origin xyz="0 0 0.030"/>
    </visual>
  </link>

  <link name="neck_pitch">
    <visual>
      <geometry>
	<box size="0.020 0.040 0.050"/>
      </geometry>
      <material name="darkgray"/>
      <origin xyz="0 0 0.020"/>
    </visual>
  </link>

  <link name="camera_link">
    <visual>
      <geometry>
	<box size="0.040 0.180 0.025"/>
      </geometry>
      <material name="darkgray"/>
    </visual>
  </link>
  
  
  <!-- Joints -->
  
  <joint name="leftwing_joint" type="fixed">
    <parent link="base_link"/>
    <child link="left_plate"/>
    <origin xyz="0.005 ${0.055 - 0.024} 0.0125" rpy="0 0 0"/>
  </joint>

  <joint name="rightwing_joint" type="fixed">
    <parent link="base_link"/>
    <child link="right_plate"/>
    <origin xyz="0.005 ${-0.055 + 0.024} 0.0125" rpy="0 0 0"/>
  </joint>

  <joint name="rear_joint" type="fixed">
    <parent link="base_link"/>
    <child link="rear_link"/>
    <origin xyz="${-0.045 + 0.024} 0.00 0.0145" rpy="0 0 0"/>
  </joint>

  <joint name="topplate_joint" type="fixed">
    <parent link="base_link"/>
    <child link="top_plate"/>
    <origin xyz="${-0.045 + 0.0241} 0.00 0.0145" rpy="0 0 0"/>
  </joint>

  <joint name="rear_omni" type="continuous">
    <parent link="base_link"/>
    <child link="omni_wheel"/>
    <origin xyz="${-0.045 - 0.06625} 0.0 0.0091" rpy="${pi/2} 0 0"/>
    <axis xyz="0 0 1"/>
  </joint>
    
  <joint name="left_wheel" type="continuous">
    <parent link="base_link"/>
    <child link="wheel_L"/>
    <origin xyz="0 0.1433 0.004" rpy="${pi/2} 0 0"/>
    <axis xyz="0 0 1"/>
  </joint>
    
  <joint name="right_wheel" type="continuous">
    <parent link="base_link"/>
    <child link="wheel_R"/>
    <origin xyz="0 -0.1433 0.004" rpy="${pi/2} 0 0"/>
    <axis xyz="0 0 1"/>
  </joint>
  
  <joint name="neck_yaw_j" type="revolute">
    <parent link="base_link"/>
    <child link="neck_yaw"/>
    <origin xyz="0.0 0.0 0.01" rpy="0 0 0"/>
    <limit effort="30" velocity="1" lower="-1.75" upper="1.75"/>
    <axis xyz="0 0 1"/>
  </joint>

  <joint name="neck_pitch_j" type="revolute">
    <parent link="neck_yaw"/>
    <child link="neck_pitch"/>
    <origin xyz="0.0 0.0 0.065" rpy="0 0 0"/>
    <limit effort="30" velocity="1" lower="-0.5" upper="0.8"/>
    <axis xyz="0 1 0"/>
  </joint>

  <joint name="camera_pitch" type="fixed">
    <parent link="neck_pitch"/>
    <child link="camera_link"/>
    <origin xyz="0.0 0.0 0.0704" rpy="0 0 0"/>
  </joint>    

</robot>
